Workbook
Name abc: #REF!
Name Beneficio_Porcent: #REF!
Name categoria: #REF!
Name Categoria_Personal: #REF!
Name ce_CodigoImagen: #REF!
Name Celular: #REF!
Name Clientes: #REF!
Name Cost_TotalGastos: '[1]Hoja de Costos'!$D$85
Name Costo_Mat: #REF!
Name Costo_MO: #REF!
Name Costo_Reprocesos: #REF!
Name Costo_Servicios: #REF!
Name Costo_Suministros: #REF!
Name CostoTotal: #REF!
Name Depreciacion_Total: #REF!
Name descripcion: #REF!
Name Destino: #REF!
Name DiasMes: #REF!
Name Direccion: #REF!
Name DNI: #REF!
Name ExcesoMat_Porcent: #REF!
Name Factor_Depreciacion: #REF!
Name fecha_venta: #REF!
Name Gasto_Depreciacion: #REF!
Name Gasto_Desarrollo: #REF!
Name Gasto_Financiero: #REF!
Name Gasto_ServiciosInd: #REF!
Name Gasto_Sueldos: #REF!
Name Gasto_SumHer: #REF!
Name HojaCostos_Codigo: '[1]Hoja de Costos'!$C$1
Name HorasJornada: #REF!
Name Item_Maquina: #REF!
Name MinHora: #REF!
Name Monto: #REF!
Name Monto_letras: #REF!
Name number_boleta: #REF!
Name PRODUCTO: #REF!
Name PrototipoMOD_Porcent: #REF!
Name ReprocesoMat_Porcent: #REF!
Name ReprocesoMO_Porcent: #REF!
Name T_MAQUINA_BORDADO: #REF!
Name Valor_Inicial: #REF!
Name Valor_Residual: #REF!
Name Vida_Util: #REF!

Sheet RECETAS
L1: Columna2
L2: TEL0000149 | M2: insert into P_DFORM(CDG_PROD,CDG_CONP,CAN_PROD) VALUES(' | N2: =M2&Tabla3[[#This Row],[CODIGO PRODUCTO TERMINADO]]&"','"&L2&"',"&Tabla3[[#This Row],[CANTIDAD MATERIAL (M)]]&");" -> #VALUE!
L3: TEL0000040 | M3: insert into P_DFORM(CDG_PROD,CDG_CONP,CAN_PROD) VALUES(' | N3: =M3&Tabla3[[#This Row],[CODIGO PRODUCTO TERMINADO]]&"','"&L3&"',"&Tabla3[[#This Row],[CANTIDAD MATERIAL (M)]]&");" -> #VALUE!
L4: TEL0000042 | M4: insert into P_DFORM(CDG_PROD,CDG_CONP,CAN_PROD) VALUES(' | N4: =M4&Tabla3[[#This Row],[CODIGO PRODUCTO TERMINADO]]&"','"&L4&"',"&Tabla3[[#This Row],[CANTIDAD MATERIAL (M)]]&");" -> #VALUE!
L5: TEL0000191 | M5: insert into P_DFORM(CDG_PROD,CDG_CONP,CAN_PROD) VALUES(' | N5: =M5&Tabla3[[#This Row],[CODIGO PRODUCTO TERMINADO]]&"','"&L5&"',"&Tabla3[[#This Row],[CANTIDAD MATERIAL (M)]]&");" -> #VALUE!
L6: AVI0000034 | M6: insert into P_DFORM(CDG_PROD,CDG_CONP,CAN_PROD) VALUES(' | N6: =M6&Tabla3[[#This Row],[CODIGO PRODUCTO TERMINADO]]&"','"&L6&"',"&Tabla3[[#This Row],[CANTIDAD MATERIAL (M)]]&");" -> #VALUE!
L7: AVI0000039 | M7: insert into P_DFORM(CDG_PROD,CDG_CONP,CAN_PROD) VALUES(' | N7: =M7&Tabla3[[#This Row],[CODIGO PRODUCTO TERMINADO]]&"','"&L7&"',"&Tabla3[[#This Row],[CANTIDAD MATERIAL (M)]]&");" -> #VALUE!
L8: AVI0000135 | M8: insert into P_DFORM(CDG_PROD,CDG_CONP,CAN_PROD) VALUES(' | N8: =M8&Tabla3[[#This Row],[CODIGO PRODUCTO TERMINADO]]&"','"&L8&"',"&Tabla3[[#This Row],[CANTIDAD MATERIAL (M)]]&");" -> #VALUE!
L9: TEL0000192 | M9: insert into P_DFORM(CDG_PROD,CDG_CONP,CAN_PROD) VALUES(' | N9: =M9&Tabla3[[#This Row],[CODIGO PRODUCTO TERMINADO]]&"','"&L9&"',"&Tabla3[[#This Row],[CANTIDAD MATERIAL (M)]]&");" -> #VALUE!
L10: AVI0000031 | M10: insert into P_DFORM(CDG_PROD,CDG_CONP,CAN_PROD) VALUES(' | N10: =M10&Tabla3[[#This Row],[CODIGO PRODUCTO TERMINADO]]&"','"&L10&"',"&Tabla3[[#This Row],[CANTIDAD MATERIAL (M)]]&");" -> #VALUE!
L11: TEL0000149 | M11: insert into P_DFORM(CDG_PROD,CDG_CONP,CAN_PROD) VALUES(' | N11: =M11&Tabla3[[#This Row],[CODIGO PRODUCTO TERMINADO]]&"','"&L11&"',"&Tabla3[[#This Row],[CANTIDAD MATERIAL (M)]]&");" -> #VALUE!
L12: TEL0000040 | M12: insert into P_DFORM(CDG_PROD,CDG_CONP,CAN_PROD) VALUES(' | N12: =M12&Tabla3[[#This Row],[CODIGO PRODUCTO TERMINADO]]&"','"&L12&"',"&Tabla3[[#This Row],[CANTIDAD MATERIAL (M)]]&");" -> #VALUE!
L13: TEL0000042 | M13: insert into P_DFORM(CDG_PROD,CDG_CONP,CAN_PROD) VALUES(' | N13: =M13&Tabla3[[#This Row],[CODIGO PRODUCTO TERMINADO]]&"','"&L13&"',"&Tabla3[[#This Row],[CANTIDAD MATERIAL (M)]]&");" -> #VALUE!
... L20: TEL0000149 | M20: insert into P_DFORM(CDG_PROD,CDG_CONP,CAN_PROD) VALUES(' | N20: =M20&Tabla3[[#This Row],[CODIGO PRODUCTO TERMINADO]]&"','"&L20&"',"&Tabla3[[#This Row],[CANTIDAD MATERIAL (M)]]&");" -> #VALUE!
A21: CODIGO PRODUCTO TERMINADO | B21: CATEGORIA | C21: PRODUCTO TERMINADO | D21: CLASIFICACIÓN | E21: DESCRIPCION MATERIAL | F21: CANTIDAD MATERIAL (M) | G21: UNIDAD DE MEDIDA | H21: Columna2 | I21: Columna3 | J21: SI SALE A SERVICIO | K21: CANTIDAD QUE SE QUEDA EN ALMACEN | L21: TEL0000040 | M21: insert into P_DFORM(CDG_PROD,CDG_CONP,CAN_PROD) VALUES(' | N21: =M21&Tabla3[[#This Row],[CODIGO PRODUCTO TERMINADO]]&"','"&L21&"',"&Tabla3[[#This Row],[CANTIDAD MATERIAL (M)]]&");" -> #VALUE!
A22: FP02 | B22: FIESTAS PATRIAS | C22: SAN MARTIN #4 | D22: TELA | E22: GASA DE 3MM | F22: 0.065 | H22: =VLOOKUP(Tabla3[[#This Row],[DESCRIPCION MATERIAL]],'CODIGO MAT'!$C$2:$D$390,2,FALSE) -> TEL0000149 | J22: 1 | K22: 0 | L22: TEL0000042 | M22: insert into P_DFORM(CDG_PROD,CDG_CONP,CAN_PROD) VALUES(' | N22: =M22&Tabla3[[#This Row],[CODIGO PRODUCTO TERMINADO]]&"','"&L22&"',"&Tabla3[[#This Row],[CANTIDAD MATERIAL (M)]]&");" -> insert into P_DFORM(CDG_PROD,CDG_CONP,CAN_PROD) VALUES('FP02 ','TEL0000042',0.065);
A23: FP02 | B23: FIESTAS PATRIAS | C23: SAN MARTIN #4 | D23: TELA | E23: SERMAT BLANCO | F23: 0.41 | H23: =VLOOKUP(Tabla3[[#This Row],[DESCRIPCION MATERIAL]],'CODIGO MAT'!$C$2:$D$390,2,FALSE) -> TEL0000040 | J23: 1 | K23: 0 | L23: TEL0000191 | M23: insert into P_DFORM(CDG_PROD,CDG_CONP,CAN_PROD) VALUES(' | N23: =M23&Tabla3[[#This Row],[CODIGO PRODUCTO TERMINADO]]&"','"&L23&"',"&Tabla3[[#This Row],[CANTIDAD MATERIAL (M)]]&");" -> insert into P_DFORM(CDG_PROD,CDG_CONP,CAN_PROD) VALUES('FP02 ','TEL0000191',0.41);
A24: FP02 | B24: FIESTAS PATRIAS | C24: SAN MARTIN #4 | D24: TELA | E24: SERMAT AZULINO | F24: 0.532 | H24: =VLOOKUP(Tabla3[[#This Row],[DESCRIPCION MATERIAL]],'CODIGO MAT'!$C$2:$D$390,2,FALSE) -> TEL0000042 | J24: 1 | K24: 0 | L24: AVI0000034 | M24: insert into P_DFORM(CDG_PROD,CDG_CONP,CAN_PROD) VALUES(' | N24: =M24&Tabla3[[#This Row],[CODIGO PRODUCTO TERMINADO]]&"','"&L24&"',"&Tabla3[[#This Row],[CANTIDAD MATERIAL (M)]]&");" -> insert into P_DFORM(CDG_PROD,CDG_CONP,CAN_PROD) VALUES('FP02 ','AVI0000034',0.532);
A25: FP02 | B25: FIESTAS PATRIAS | C25: SAN MARTIN #4 | D25: TELA | E25: SERMAT LAMINADO AZULINO | F25: 0.11 | H25: =VLOOKUP(Tabla3[[#This Row],[DESCRIPCION MATERIAL]],'CODIGO MAT'!$C$2:$D$390,2,FALSE) -> TEL0000191 | J25: 1 | K25: 0 | L25: AVI0000039 | M25: insert into P_DFORM(CDG_PROD,CDG_CONP,CAN_PROD) VALUES(' | N25: =M25&Tabla3[[#This Row],[CODIGO PRODUCTO TERMINADO]]&"','"&L25&"',"&Tabla3[[#This Row],[CANTIDAD MATERIAL (M)]]&");" -> insert into P_DFORM(CDG_PROD,CDG_CONP,CAN_PROD) VALUES('FP02 ','AVI0000039',0.11);
A26: FP02 | B26: FIESTAS PATRIAS | C26: SAN MARTIN #4 | D26: AVIO | E26: GRECA TRINCHI DORADO | F26: 2.88 | H26: =VLOOKUP(Tabla3[[#This Row],[DESCRIPCION MATERIAL]],'CODIGO MAT'!$C$2:$D$390,2,FALSE) -> AVI0000034 | J26: 1 | K26: 0 | L26: AVI0000135 | M26: insert into P_DFORM(CDG_PROD,CDG_CONP,CAN_PROD) VALUES(' | N26: =M26&Tabla3[[#This Row],[CODIGO PRODUCTO TERMINADO]]&"','"&L26&"',"&Tabla3[[#This Row],[CANTIDAD MATERIAL (M)]]&");" -> insert into P_DFORM(CDG_PROD,CDG_CONP,CAN_PROD) VALUES('FP02 ','AVI0000135',2.88);
A27: FP02 | B27: FIESTAS PATRIAS | C27: SAN MARTIN #4 | D27: AVIO | E27: FLECO BANDERIN DORADO | F27: 0.51 | H27: =VLOOKUP(Tabla3[[#This Row],[DESCRIPCION MATERIAL]],'CODIGO MAT'!$C$2:$D$390,2,FALSE) -> AVI0000039 | J27: 1 | K27: 0 | L27: TEL0000192 | M27: insert into P_DFORM(CDG_PROD,CDG_CONP,CAN_PROD) VALUES(' | N27: =M27&Tabla3[[#This Row],[CODIGO PRODUCTO TERMINADO]]&"','"&L27&"',"&Tabla3[[#This Row],[CANTIDAD MATERIAL (M)]]&");" -> insert into P_DFORM(CDG_PROD,CDG_CONP,CAN_PROD) VALUES('FP02 ','TEL0000192',0.51);
A28: FP02 | B28: FIESTAS PATRIAS | C28: SAN MARTIN #4 | D28: AVIO | E28: BOTON ANCLA #28 DORADO | F28: 6 | H28: =VLOOKUP(Tabla3[[#This Row],[DESCRIPCION MATERIAL]],'CODIGO MAT'!$C$2:$D$390,2,FALSE) -> AVI0000135 | L28: AVI0000031 | M28: insert into P_DFORM(CDG_PROD,CDG_CONP,CAN_PROD) VALUES(' | N28: =M28&Tabla3[[#This Row],[CODIGO PRODUCTO TERMINADO]]&"','"&L28&"',"&Tabla3[[#This Row],[CANTIDAD MATERIAL (M)]]&");" -> insert into P_DFORM(CDG_PROD,CDG_CONP,CAN_PROD) VALUES('FP02 ','AVI0000031',6);
A29: FP02 | B29: FIESTAS PATRIAS | C29: SAN MARTIN #4 | D29: TELA | E29: LATEX LICRADO LAMINADO DORADO | F29: 0.012 | H29: =VLOOKUP(Tabla3[[#This Row],[DESCRIPCION MATERIAL]],'CODIGO MAT'!$C$2:$D$390,2,FALSE) -> TEL0000192 | L29: TEL0000149 | M29: insert into P_DFORM(CDG_PROD,CDG_CONP,CAN_PROD) VALUES(' | N29: =M29&Tabla3[[#This Row],[CODIGO PRODUCTO TERMINADO]]&"','"&L29&"',"&Tabla3[[#This Row],[CANTIDAD MATERIAL (M)]]&");" -> insert into P_DFORM(CDG_PROD,CDG_CONP,CAN_PROD) VALUES('FP02 ','TEL0000149',0.012);
A30: FP02 | B30: FIESTAS PATRIAS | C30: SAN MARTIN #4 | D30: AVIO | E30: GRECA 511 DORADO | F30: 0.31 | H30: =VLOOKUP(Tabla3[[#This Row],[DESCRIPCION MATERIAL]],'CODIGO MAT'!$C$2:$D$390,2,FALSE) -> AVI0000031 | L30: TEL0000040 | M30: insert into P_DFORM(CDG_PROD,CDG_CONP,CAN_PROD) VALUES(' | N30: =M30&Tabla3[[#This Row],[CODIGO PRODUCTO TERMINADO]]&"','"&L30&"',"&Tabla3[[#This Row],[CANTIDAD MATERIAL (M)]]&");" -> insert into P_DFORM(CDG_PROD,CDG_CONP,CAN_PROD) VALUES('FP02 ','TEL0000040',0.31);
A31: FP03 | B31: FIESTAS PATRIAS | C31: SAN MARTIN #6 | D31: TELA | E31: GASA DE 3MM | F31: 0.065 | H31: =VLOOKUP(Tabla3[[#This Row],[DESCRIPCION MATERIAL]],'CODIGO MAT'!$C$2:$D$390,2,FALSE) -> TEL0000149 | J31: 1 | K31: 0 | L31: TEL0000042 | M31: insert into P_DFORM(CDG_PROD,CDG_CONP,CAN_PROD) VALUES(' | N31: =M31&Tabla3[[#This Row],[CODIGO PRODUCTO TERMINADO]]&"','"&L31&"',"&Tabla3[[#This Row],[CANTIDAD MATERIAL (M)]]&");" -> insert into P_DFORM(CDG_PROD,CDG_CONP,CAN_PROD) VALUES('FP03','TEL0000042',0.065);
A32: FP03 | B32: FIESTAS PATRIAS | C32: SAN MARTIN #6 | D32: TELA | E32: SERMAT BLANCO | F32: 0.452 | H32: =VLOOKUP(Tabla3[[#This Row],[DESCRIPCION MATERIAL]],'CODIGO MAT'!$C$2:$D$390,2,FALSE) -> TEL0000040 | J32: 1 | K32: 0 | L32: TEL0000191 | M32: insert into P_DFORM(CDG_PROD,CDG_CONP,CAN_PROD) VALUES(' | N32: =M32&Tabla3[[#This Row],[CODIGO PRODUCTO TERMINADO]]&"','"&L32&"',"&Tabla3[[#This Row],[CANTIDAD MATERIAL (M)]]&");" -> insert into P_DFORM(CDG_PROD,CDG_CONP,CAN_PROD) VALUES('FP03','TEL0000191',0.452);
A33: FP03 | B33: FIESTAS PATRIAS | C33: SAN MARTIN #6 | D33: TELA | E33: SERMAT AZULINO | F33: 0.618 | H33: =VLOOKUP(Tabla3[[#This Row],[DESCRIPCION MATERIAL]],'CODIGO MAT'!$C$2:$D$390,2,FALSE) -> TEL0000042 | J33: 1 | K33: 0 | L33: AVI0000034 | M33: insert into P_DFORM(CDG_PROD,CDG_CONP,CAN_PROD) VALUES(' | N33: =M33&Tabla3[[#This Row],[CODIGO PRODUCTO TERMINADO]]&"','"&L33&"',"&Tabla3[[#This Row],[CANTIDAD MATERIAL (M)]]&");" -> insert into P_DFORM(CDG_PROD,CDG_CONP,CAN_PROD) VALUES('FP03','AVI0000034',0.618);
A34: FP03 | B34: FIESTAS PATRIAS | C34: SAN MARTIN #6 | D34: TELA | E34: SERMAT LAMINADO AZULINO | F34: 0.11 | H34: =VLOOKUP(Tabla3[[#This Row],[DESCRIPCION MATERIAL]],'CODIGO MAT'!$C$2:$D$390,2,FALSE) -> TEL0000191 | J34: 1 | K34: 0 | L34: AVI0000039 | M34: insert into P_DFORM(CDG_PROD,CDG_CONP,CAN_PROD) VALUES(' | N34: =M34&Tabla3[[#This Row],[CODIGO PRODUCTO TERMINADO]]&"','"&L34&"',"&Tabla3[[#This Row],[CANTIDAD MATERIAL (M)]]&");" -> insert into P_DFORM(CDG_PROD,CDG_CONP,CAN_PROD) VALUES('FP03','AVI0000039',0.11);
A35: FP03 | B35: FIESTAS PATRIAS | C35: SAN MARTIN #6 | D35: AVIO | E35: GRECA TRINCHI DORADO | F35: 2.93 | H35: =VLOOKUP(Tabla3[[#This Row],[DESCRIPCION MATERIAL]],'CODIGO MAT'!$C$2:$D$390,2,FALSE) -> AVI0000034 | J35: 1 | K35: 0 | L35: AVI0000135 | M35: insert into P_DFORM(CDG_PROD,CDG_CONP,CAN_PROD) VALUES(' | N35: =M35&Tabla3[[#This Row],[CODIGO PRODUCTO TERMINADO]]&"','"&L35&"',"&Tabla3[[#This Row],[CANTIDAD MATERIAL (M)]]&");" -> insert into P_DFORM(CDG_PROD,CDG_CONP,CAN_PROD) VALUES('FP03','AVI0000135',2.93);
A36: FP03 | B36: FIESTAS PATRIAS | C36: SAN MARTIN #6 | D36: AVIO | E36: FLECO BANDERIN DORADO | F36: 0.51 | H36: =VLOOKUP(Tabla3[[#This Row],[DESCRIPCION MATERIAL]],'CODIGO MAT'!$C$2:$D$390,2,FALSE) -> AVI0000039 | J36: 1 | K36: 0 | L36: TEL0000192 | M36: insert into P_DFORM(CDG_PROD,CDG_CONP,CAN_PROD) VALUES(' | N36: =M36&Tabla3[[#This Row],[CODIGO PRODUCTO TERMINADO]]&"','"&L36&"',"&Tabla3[[#This Row],[CANTIDAD MATERIAL (M)]]&");" -> insert into P_DFORM(CDG_PROD,CDG_CONP,CAN_PROD) VALUES('FP03','TEL0000192',0.51);
A37: FP03 | B37: FIESTAS PATRIAS | C37: SAN MARTIN #6 | D37: AVIO | E37: BOTON ANCLA #28 DORADO | F37: 6 | H37: =VLOOKUP(Tabla3[[#This Row],[DESCRIPCION MATERIAL]],'CODIGO MAT'!$C$2:$D$390,2,FALSE) -> AVI0000135 | L37: AVI0000031 | M37: insert into P_DFORM(CDG_PROD,CDG_CONP,CAN_PROD) VALUES(' | N37: =M37&Tabla3[[#This Row],[CODIGO PRODUCTO TERMINADO]]&"','"&L37&"',"&Tabla3[[#This Row],[CANTIDAD MATERIAL (M)]]&");" -> insert into P_DFORM(CDG_PROD,CDG_CONP,CAN_PROD) VALUES('FP03','AVI0000031',6);
A38: FP03 | B38: FIESTAS PATRIAS | C38: SAN MARTIN #6 | D38: TELA | E38: LATEX LICRADO LAMINADO DORADO | F38: 0.012 | H38: =VLOOKUP(Tabla3[[#This Row],[DESCRIPCION MATERIAL]],'CODIGO MAT'!$C$2:$D$390,2,FALSE) -> TEL0000192 | L38: TEL0000149 | M38: insert into P_DFORM(CDG_PROD,CDG_CONP,CAN_PROD) VALUES(' | N38: =M38&Tabla3[[#This Row],[CODIGO PRODUCTO TERMINADO]]&"','"&L38&"',"&Tabla3[[#This Row],[CANTIDAD MATERIAL (M)]]&");" -> insert into P_DFORM(CDG_PROD,CDG_CONP,CAN_PROD) VALUES('FP03','TEL0000149',0.012);
A39: FP03 | B39: FIESTAS PATRIAS | C39: SAN MARTIN #6 | D39: AVIO | E39: GRECA 511 DORADO | F39: 0.31 | H39: =VLOOKUP(Tabla3[[#This Row],[DESCRIPCION MATERIAL]],'CODIGO MAT'!$C$2:$D$390,2,FALSE) -> AVI0000031 | L39: TEL0000040 | M39: insert into P_DFORM(CDG_PROD,CDG_CONP,CAN_PROD) VALUES(' | N39: =M39&Tabla3[[#This Row],[CODIGO PRODUCTO TERMINADO]]&"','"&L39&"',"&Tabla3[[#This Row],[CANTIDAD MATERIAL (M)]]&");" -> insert into P_DFORM(CDG_PROD,CDG_CONP,CAN_PROD) VALUES('FP03','TEL0000040',0.31);
A40: FP04 | B40: FIESTAS PATRIAS | C40: SAN MARTIN #8 | D40: TELA | E40: GASA DE 3MM | F40: 0.11 | H40: =VLOOKUP(Tabla3[[#This Row],[DESCRIPCION MATERIAL]],'CODIGO MAT'!$C$2:$D$390,2,FALSE) -> TEL0000149 | J40: 1 | K40: 0 | L40: TEL0000042 | M40: insert into P_DFORM(CDG_PROD,CDG_CONP,CAN_PROD) VALUES(' | N40: =M40&Tabla3[[#This Row],[CODIGO PRODUCTO TERMINADO]]&"','"&L40&"',"&Tabla3[[#This Row],[CANTIDAD MATERIAL (M)]]&");" -> insert into P_DFORM(CDG_PROD,CDG_CONP,CAN_PROD) VALUES('FP04','TEL0000042',0.11);
A41: FP04 | B41: FIESTAS PATRIAS | C41: SAN MARTIN #8 | D41: TELA | E41: SERMAT BLANCO | F41: 0.52 | H41: =VLOOKUP(Tabla3[[#This Row],[DESCRIPCION MATERIAL]],'CODIGO MAT'!$C$2:$D$390,2,FALSE) -> TEL0000040 | J41: 1 | K41: 0 | L41: TEL0000191 | M41: insert into P_DFORM(CDG_PROD,CDG_CONP,CAN_PROD) VALUES(' | N41: =M41&Tabla3[[#This Row],[CODIGO PRODUCTO TERMINADO]]&"','"&L41&"',"&Tabla3[[#This Row],[CANTIDAD MATERIAL (M)]]&");" -> insert into P_DFORM(CDG_PROD,CDG_CONP,CAN_PROD) VALUES('FP04','TEL0000191',0.52);
A42: FP04 | B42: FIESTAS PATRIAS | C42: SAN MARTIN #8 | D42: TELA | E42: SERMAT AZULINO | F42: 0.71 | H42: =VLOOKUP(Tabla3[[#This Row],[DESCRIPCION MATERIAL]],'CODIGO MAT'!$C$2:$D$390,2,FALSE) -> TEL0000042 | J42: 1 | K42: 0 | L42: AVI0000034 | M42: insert into P_DFORM(CDG_PROD,CDG_CONP,CAN_PROD) VALUES(' | N42: =M42&Tabla3[[#This Row],[CODIGO PRODUCTO TERMINADO]]&"','"&L42&"',"&Tabla3[[#This Row],[CANTIDAD MATERIAL (M)]]&");" -> insert into P_DFORM(CDG_PROD,CDG_CONP,CAN_PROD) VALUES('FP04','AVI0000034',0.71);
A43: FP04 | B43: FIESTAS PATRIAS | C43: SAN MARTIN #8 | D43: TELA | E43: SERMAT LAMINADO AZULINO | F43: 0.11 | H43: =VLOOKUP(Tabla3[[#This Row],[DESCRIPCION MATERIAL]],'CODIGO MAT'!$C$2:$D$390,2,FALSE) -> TEL0000191 | J43: 1 | K43: 0 | L43: AVI0000039 | M43: insert into P_DFORM(CDG_PROD,CDG_CONP,CAN_PROD) VALUES(' | N43: =M43&Tabla3[[#This Row],[CODIGO PRODUCTO TERMINADO]]&"','"&L43&"',"&Tabla3[[#This Row],[CANTIDAD MATERIAL (M)]]&");" -> insert into P_DFORM(CDG_PROD,CDG_CONP,CAN_PROD) VALUES('FP04','AVI0000039',0.11);
A44: FP04 | B44: FIESTAS PATRIAS | C44: SAN MARTIN #8 | D44: AVIO | E44: GRECA TRINCHI DORADO | F44: 3.06 | H44: =VLOOKUP(Tabla3[[#This Row],[DESCRIPCION MATERIAL]],'CODIGO MAT'!$C$2:$D$390,2,FALSE) -> AVI0000034 | J44: 1 | K44: 0 | L44: AVI0000135 | M44: insert into P_DFORM(CDG_PROD,CDG_CONP,CAN_PROD) VALUES(' | N44: =M44&Tabla3[[#This Row],[CODIGO PRODUCTO TERMINADO]]&"','"&L44&"',"&Tabla3[[#This Row],[CANTIDAD MATERIAL (M)]]&");" -> insert into P_DFORM(CDG_PROD,CDG_CONP,CAN_PROD) VALUES('FP04','AVI0000135',3.06);
A45: FP04 | B45: FIESTAS PATRIAS | C45: SAN MARTIN #8 | D45: AVIO | E45: FLECO BANDERIN DORADO | F45: 0.51 | H45: =VLOOKUP(Tabla3[[#This Row],[DESCRIPCION MATERIAL]],'CODIGO MAT'!$C$2:$D$390,2,FALSE) -> AVI0000039 | J45: 1 | K45: 0 | L45: TEL0000192 | M45: insert into P_DFORM(CDG_PROD,CDG_CONP,CAN_PROD) VALUES(' | N45: =M45&Tabla3[[#This Row],[CODIGO PRODUCTO TERMINADO]]&"','"&L45&"',"&Tabla3[[#This Row],[CANTIDAD MATERIAL (M)]]&");" -> insert into P_DFORM(CDG_PROD,CDG_CONP,CAN_PROD) VALUES('FP04','TEL0000192',0.51);
A46: FP04 | B46: FIESTAS PATRIAS | C46: SAN MARTIN #8 | D46: AVIO | E46: BOTON ANCLA #28 DORADO | F46: 6 | H46: =VLOOKUP(Tabla3[[#This Row],[DESCRIPCION MATERIAL]],'CODIGO MAT'!$C$2:$D$390,2,FALSE) -> AVI0000135 | L46: AVI0000031 | M46: insert into P_DFORM(CDG_PROD,CDG_CONP,CAN_PROD) VALUES(' | N46: =M46&Tabla3[[#This Row],[CODIGO PRODUCTO TERMINADO]]&"','"&L46&"',"&Tabla3[[#This Row],[CANTIDAD MATERIAL (M)]]&");" -> insert into P_DFORM(CDG_PROD,CDG_CONP,CAN_PROD) VALUES('FP04','AVI0000031',6);
...

Sheet MATERIALES
B1: MATERIALES | E1: CON IGV
B2: CATEGORIA | C2: MATERIALES | D2: UNIDAD DE COMPRA | E2: PRECIO | F2: Columna1 | G2: UNIDAD
B3: INSUMOS | C3: BARNIS | D3: Kg | E3: 60 | F3: 1 | G3: kg
B4: INSUMOS | C4: BASE BB BLANCO | D4: Kg | E4: 16 | F4: 1 | G4: kg
B5: TELA | C5: BIOCUERO P APLICACIÓN DORADO | D5: m | E5: 12 | F5: 1 | G5: =IFERROR(VLOOKUP(T_Materiales[[#This Row],[UNIDAD DE COMPRA]],#REF!,3,0),"")
B6: TELA | C6: BIOCUERO P APLICACIÓN PLATEADO | D6: m | E6: 12 | F6: 1 | G6: =IFERROR(VLOOKUP(T_Materiales[[#This Row],[UNIDAD DE COMPRA]],#REF!,3,0),"")
B7: TELA | C7: BIOCUERO P ESTAMPAR DORADO | D7: m | E7: 15 | F7: 1 | G7: =IFERROR(VLOOKUP(T_Materiales[[#This Row],[UNIDAD DE COMPRA]],#REF!,3,0),"")
B8: TELA | C8: BIOCUERO P ESTAMPAR PLATEADO | D8: m | E8: 15 | F8: 1 | G8: =IFERROR(VLOOKUP(T_Materiales[[#This Row],[UNIDAD DE COMPRA]],#REF!,3,0),"")
B9: AVIOS | C9: BLONDA CHAVELA BLANCA | D9: m | E9: 4 | F9: 1 | G9: =IFERROR(VLOOKUP(T_Materiales[[#This Row],[UNIDAD DE COMPRA]],#REF!,3,0),"")
B10: AVIOS | C10: BLONDA SABROSA BLANCA | D10: Rollo (m) | E10: 50 | F10: 1 | G10: =IFERROR(VLOOKUP(T_Materiales[[#This Row],[UNIDAD DE COMPRA]],#REF!,3,0),"")
B11: AVIOS | C11: BOTON LENTEJA #28 GUINDA | D11: mazo | E11: 60 | F11: 1 | G11: unidad
B12: AVIOS | C12: BOTON ANCLA #28 DORADO | D12: Millar | E12: 50 | F12: 1 | G12: =IFERROR(VLOOKUP(T_Materiales[[#This Row],[UNIDAD DE COMPRA]],#REF!,3,0),"")
B13: AVIOS | C13: BOTON ANCLA #32 DORADO | D13: Millar | E13: 75 | F13: 1 | G13: =IFERROR(VLOOKUP(T_Materiales[[#This Row],[UNIDAD DE COMPRA]],#REF!,3,0),"")
B14: AVIOS | C14: BOTON DORADO #24 | D14: Millar | E14: 30 | F14: 1 | G14: =IFERROR(VLOOKUP(T_Materiales[[#This Row],[UNIDAD DE COMPRA]],#REF!,3,0),"")
B15: AVIOS | C15: BOTON DORADO #28 | D15: Millar | E15: 45 | F15: 1 | G15: =IFERROR(VLOOKUP(T_Materiales[[#This Row],[UNIDAD DE COMPRA]],#REF!,3,0),"")
B16: AVIOS | C16: BOTON DORADO #34 DORADO | D16: Millar | E16: 65 | F16: 1 | G16: =IFERROR(VLOOKUP(T_Materiales[[#This Row],[UNIDAD DE COMPRA]],#REF!,3,0),"")
B17: AVIOS | C17: BOTON DORADO HONGUITO #34 | D17: Millar | E17: 85 | F17: 1 | G17: =IFERROR(VLOOKUP(T_Materiales[[#This Row],[UNIDAD DE COMPRA]],#REF!,3,0),"")
B18: AVIOS | C18: BOTON LENTEJA #28 AMARILLO BRAZIL | D18: Mazo | E18: 60 | F18: 1 | G18: =IFERROR(VLOOKUP(T_Materiales[[#This Row],[UNIDAD DE COMPRA]],#REF!,3,0),"")
B19: AVIOS | C19: BOTON LENTEJA #28 AMARILLO ORO | D19: Mazo | E19: 60 | F19: 1 | G19: unidad
B20: AVIOS | C20: BOTON LENTEJA #28 AZUL | D20: Mazo | E20: 60 | F20: 1 | G20: =IFERROR(VLOOKUP(T_Materiales[[#This Row],[UNIDAD DE COMPRA]],#REF!,3,0),"")
B21: AVIOS | C21: BOTON LENTEJA #28 AZULINO | D21: Mazo | E21: 60 | F21: 1 | G21: =IFERROR(VLOOKUP(T_Materiales[[#This Row],[UNIDAD DE COMPRA]],#REF!,3,0),"")
B22: AVIOS | C22: BOTON LENTEJA #28 BLANCO | D22: Mazo | E22: 60 | F22: 1 | G22: =IFERROR(VLOOKUP(T_Materiales[[#This Row],[UNIDAD DE COMPRA]],#REF!,3,0),"")
B23: AVIOS | C23: BOTON LENTEJA #28 FUXIA | D23: Mazo | E23: 60 | F23: 1 | G23: =IFERROR(VLOOKUP(T_Materiales[[#This Row],[UNIDAD DE COMPRA]],#REF!,3,0),"")
B24: AVIOS | C24: BOTON LENTEJA #28 ROJO | D24: Mazo | E24: 60 | F24: 1 | G24: =IFERROR(VLOOKUP(T_Materiales[[#This Row],[UNIDAD DE COMPRA]],#REF!,3,0),"")
B25: AVIOS | C25: BOTON LENTEJA #28 ROSADO | D25: Mazo | E25: 60 | F25: 1 | G25: =IFERROR(VLOOKUP(T_Materiales[[#This Row],[UNIDAD DE COMPRA]],#REF!,3,0),"")
B26: AVIOS | C26: BOTON LENTEJA #28 TURQUEZA | D26: Mazo | E26: 60 | F26: 1 | G26: =IFERROR(VLOOKUP(T_Materiales[[#This Row],[UNIDAD DE COMPRA]],#REF!,3,0),"")
B27: AVIOS | C27: BOTON LENTEJA #28 VERDE MANZANA | D27: Mazo | E27: 60 | F27: 1 | G27: =IFERROR(VLOOKUP(T_Materiales[[#This Row],[UNIDAD DE COMPRA]],#REF!,3,0),"")
B28: AVIOS | C28: BOTON LENTEJA #34 AMARILLO BRAZIL | D28: Mazo | E28: 60 | F28: 1 | G28: =IFERROR(VLOOKUP(T_Materiales[[#This Row],[UNIDAD DE COMPRA]],#REF!,3,0),"")
B29: AVIOS | C29: BOTON LENTEJA #34 ROJO | D29: Mazo | E29: 60 | F29: 1 | G29: =IFERROR(VLOOKUP(T_Materiales[[#This Row],[UNIDAD DE COMPRA]],#REF!,3,0),"")
B30: AVIOS | C30: BOTON PARA EVILLA | D30: Ciento | E30: 8 | F30: 1 | G30: =IFERROR(VLOOKUP(T_Materiales[[#This Row],[UNIDAD DE COMPRA]],#REF!,3,0),"")
B31: TELA | C31: BROCADO AMARILLO BRAZIL | D31: m | E31: 5 | F31: 1 | G31: =IFERROR(VLOOKUP(T_Materiales[[#This Row],[UNIDAD DE COMPRA]],#REF!,3,0),"")
... B70: AVIOS | C70: CINTA SATINADA 1CM VERDE LORO | D70: pieza | E70: 1.2 | F70: 1 | G70: =IFERROR(VLOOKUP(T_Materiales[[#This Row],[UNIDAD DE COMPRA]],#REF!,3,0),"")
B71: AVIOS | C71: CINTA SATINADA 2.5CM AMARILLO BRAZIL | D71: Rollo (m) | E71: 0.17 | F71: 1 | G71: =IFERROR(VLOOKUP(T_Materiales[[#This Row],[UNIDAD DE COMPRA]],[2]!T_Equivalencias[#All],3,0),"")
B72: AVIOS | C72: CINTA SATINADA 2.5CM AMARILLO ORO | D72: Rollo (m) | E72: 0.17 | F72: 1 | G72: =IFERROR(VLOOKUP(T_Materiales[[#This Row],[UNIDAD DE COMPRA]],#REF!,3,0),"")
B73: AVIOS | C73: CINTA SATINADA 2.5CM BLANCO | D73: Rollo (m) | E73: 0.17 | F73: 1 | G73: =IFERROR(VLOOKUP(T_Materiales[[#This Row],[UNIDAD DE COMPRA]],#REF!,3,0),"")
B74: AVIOS | C74: CINTA SATINADA 2.5CM ROJO | D74: Rollo (m) | E74: 0.17 | F74: 1 | G74: =IFERROR(VLOOKUP(T_Materiales[[#This Row],[UNIDAD DE COMPRA]],#REF!,3,0),"")
B75: AVIOS | C75: CINTA SATINADA 2.5CM VERDE LORO | D75: Rollo (m) | E75: 0.17 | F75: 1 | G75: =IFERROR(VLOOKUP(T_Materiales[[#This Row],[UNIDAD DE COMPRA]],#REF!,3,0),"")
B76: AVIOS | C76: CINTA SATINADA 4CM AMARILLO BRAZIL | D76: Rollo (m) | E76: 0.26 | F76: 1 | G76: =IFERROR(VLOOKUP(T_Materiales[[#This Row],[UNIDAD DE COMPRA]],#REF!,3,0),"")
B77: AVIOS | C77: CINTA SATINADA DE 7MM AM ORO | D77: pieza | E77: 1 | F77: 1 | G77: =IFERROR(VLOOKUP(T_Materiales[[#This Row],[UNIDAD DE COMPRA]],#REF!,3,0),"")
B78: AVIOS | C78: CINTA SATINADA DE 7MM BEIGE | D78: pieza | E78: 1 | F78: 1 | G78: =IFERROR(VLOOKUP(T_Materiales[[#This Row],[UNIDAD DE COMPRA]],#REF!,3,0),"")
...

Sheet CODIGO MAT
A1: CDG_PROD | B1: CDG_LINP | C1: DES_PROD | D1: CDG_PROD
A2: AVI0000001 | B2: 003 | C2: VICERAS PARA GORRA CHICO | D2: AVI0000001
A3: AVI0000002 | B3: 003 | C3: VICERAS PARA GORRA GRANDE | D3: AVI0000002
A4: AVI0000003 | B4: 003 | C4: PIEDRITAS BRILLANTES | D4: AVI0000003
A5: AVI0000004 | B5: 003 | C5: HILO PARA BORDAR BLANCO | D5: AVI0000004
A6: AVI0000005 | B6: 003 | C6: HILO PARA BORDAR NEGRO | D6: AVI0000005
A7: AVI0000006 | B7: 003 | C7: HILO PARA BORDAR AMARILLO BRAZIL | D7: AVI0000006
A8: AVI0000007 | B8: 003 | C8: HILO PARA BORDAR AMARILLO ORO | D8: AVI0000007
A9: AVI0000008 | B9: 003 | C9: HILO PARA BORDAR AZUL | D9: AVI0000008
A10: AVI0000009 | B10: 003 | C10: HILO PARA BORDAR AZULINO | D10: AVI0000009
A11: AVI0000010 | B11: 003 | C11: HILO PARA BORDAR VERDE JADE | D11: AVI0000010
A12: AVI0000011 | B12: 003 | C12: HILO PARA BORDAR VERDE MANZANA | D12: AVI0000011
... A351: TEL0000190 | B351: 005 | C351: LONA ESCARCHADO AZULINO | D351: TEL0000190
C352: SERMAT LAMINADO AZULINO | D352: TEL0000191
C353: LATEX LICRADO LAMINADO DORADO | D353: TEL0000192
C354: FLECO COLA DE RATA #5 DORADO | D354: AVI0000144
C355: CINTA SATINADA 2.5CM AMARILLO BRAZIL | D355: AVI0000145
C356: TETRON BLANCO | D356: AVI0000146
C357: HILO PARA BORDAR ROJO | D357: AVI0000147
C358: ELASTICO POLIESTER DE 2CM | D358: AVI0000148
C359: GIGANTOGRAFÍA INSIGNIA | D359: AVI0000149
C360: CORROSPUM AMARILLO ORO | D360: AVI0000150
C361: CORROSPUM BLANCO | D361: AVI0000151
C362: ELASTICO PILI | D362: AVI0000152
C363: BOTON LENTEJA #28 GUINDA | D363: AVI0000153
... C375: SERMAT VERDE BOTELLA | D375: TEL0000200

Sheet COSTOS DE CONFECCION
E2: PRECIO POR TALLA DE CONFECCION
B3: CATEGORIA | C3: CODIGO | D3: DESCRIPCION | E3: T0 | F3: T2 | G3: T4 | H3: T6 | I3: T8 | J3: T10 | K3: T12 | L3: T14 | M3: T16 | N3: TS | O3: TAD | P3: OJAL Y BOTON
B4: DANZAS TIPICAS | D4: PREGONERA | G4: 3.7 | H4: 3.7 | I4: 3.7 | J4: 3.7 | K4: 3.7 | L4: 3.7 | M4: 3.7
B5: DANZAS TIPICAS | D5: AREQUIPA MUJER | G5: 4 | H5: 4 | I5: 4 | J5: 4 | K5: 4 | L5: 4 | M5: 4 | N5: 5.5 | O5: 5.5
B6: DANZAS TIPICAS | D6: SELVA MUJER (RAZO) | G6: 3.5 | H6: 3.5 | I6: 3.5 | J6: 3.5 | K6: 3.5 | L6: 3.5 | M6: 3.5 | N6: 4 | O6: 4 | P6: 0.35
B7: DANZAS TIPICAS | D7: AREQUIPA HOMBRE | G7: 3.7 | H7: 3.7 | I7: 3.7 | J7: 3.7 | K7: 3.7 | L7: 3.7 | M7: 3.7 | N7: 5 | O7: 5
B8: DANZAS TIPICAS | D8: SELVA MUJER (SERMAT) | G8: 3.5 | H8: 3.5 | I8: 3.5 | J8: 3.5 | K8: 3.5 | L8: 3.5 | M8: 3.5 | N8: 4 | O8: 4
B9: DANZAS TIPICAS | D9: FESTEJO MUJER | G9: 3.5 | H9: 3.5 | I9: 3.5 | J9: 3.5 | K9: 3.5 | L9: 3.5 | M9: 3.5 | N9: 4.5 | O9: 4.5
B10: DANZAS TIPICAS | D10: LANDO HOMBRE | G10: 3.5 | H10: 3.5 | I10: 3.5 | J10: 3.5 | K10: 3.5 | L10: 3.5 | M10: 3.5 | N10: 4.5 | O10: 4.5
B11: DANZAS TIPICAS | D11: LANDO MUJER | G11: 3.7 | H11: 3.7 | I11: 3.7 | J11: 3.7 | K11: 3.7 | L11: 3.7 | M11: 3.7 | N11: 5 | O11: 5
B12: DANZAS TIPICAS | D12: SAYA HOMBRE | G12: 3.9 | H12: 3.9 | I12: 3.9 | J12: 3.9 | K12: 3.9 | L12: 3.9 | M12: 3.9 | N12: 5 | O12: 5
B13: DANZAS TIPICAS | D13: BAILE MODERNO HOMBRE | G13: 3.5 | H13: 3.5 | I13: 3.5 | J13: 3.5 | K13: 3.5 | L13: 3.5 | M13: 3.5
B14: DANZAS TIPICAS | D14: BAILE MODERNO MUJER | G14: 3.5 | H14: 3.5 | I14: 3.5 | J14: 3.5 | K14: 3.5 | L14: 3.5 | M14: 3.5
B15: DANZAS TIPICAS | D15: TRAVOLTA | G15: 2.3 | H15: 2.3 | I15: 2.3 | J15: 2.3 | K15: 2.3 | L15: 2.3 | M15: 2.3
B16: DANZAS TIPICAS | D16: HUAYLAS MUJER SANTIAGO | G16: 4.8 | H16: 4.8 | I16: 4.8 | J16: 4.8 | K16: 4.8 | L16: 4.8 | M16: 4.8 | N16: 6.5 | O16: 6.5
B17: DANZAS TIPICAS | D17: HUAYLAS HOMBRE | G17: 3.9 | H17: 3.9 | I17: 3.9 | J17: 3.9 | K17: 3.9 | L17: 3.9 | M17: 3.9 | N17: 5.5 | O17: 5.5 | P17: 0.35
B18: DANZAS TIPICAS | D18: SAYA MUJER
B19: DANZAS TIPICAS | D19: CUZQUEÑO | G19: 3.7 | H19: 3.7 | I19: 3.7 | J19: 3.7 | K19: 3.7 | L19: 3.7 | M19: 3.7 | N19: 5 | O19: 5
B20: DANZAS TIPICAS | D20: ÑUSTA | G20: 4.3 | H20: 4.3 | I20: 4.3 | J20: 4.3 | K20: 4.3 | L20: 4.3 | M20: 4.3 | N20: 6 | O20: 6
B21: DANZAS TIPICAS | D21: SANTIAGO HOMBRE | G21: 3.5 | H21: 3.5 | I21: 3.5 | J21: 3.5 | K21: 3.5 | L21: 3.5 | M21: 3.5 | N21: 4.5 | O21: 4.5
B22: DANZAS TIPICAS | D22: SELVA HOMBRE | G22: 1.6 | H22: 1.6 | I22: 1.6 | J22: 1.6 | K22: 1.6 | L22: 1.6 | M22: 1.6 | N22: 2.3 | O22: 2.3
B23: DANZAS TIPICAS | D23: FESTEJO HOMBRE | G23: 3.5 | H23: 3.5 | I23: 3.5 | J23: 3.5 | K23: 3.5 | L23: 3.5 | M23: 3.5 | N23: 4 | O23: 4
B24: DANZAS TIPICAS | D24: CHALAN | F24: 3.5 | G24: 3.5 | H24: 3.5 | I24: 3.5 | J24: 3.5 | K24: 3.5 | L24: 3.5 | M24: 3.5
B25: DANZAS TIPICAS | D25: FESTEJO PANTALON LARGO | F25: 3.5 | G25: 3.5 | H25: 3.5 | I25: 3.5 | J25: 3.5 | K25: 3.5 | L25: 3.5 | M25: 3.5 | P25: 0.35
B26: FIESTAS PATRIAS | D26: MARINA DE GALA | F26: 3.9 | G26: 3.9 | H26: 3.9 | I26: 3.9 | J26: 3.9 | K26: 3.9 | L26: 3.9 | M26: 3.9 | N26: 5 | O26: 5 | P26: 0.45
B27: FIESTAS PATRIAS | D27: MARINA MUJER | F27: 3.7 | G27: 3.7 | H27: 3.7 | I27: 3.7 | J27: 3.7 | K27: 3.7 | L27: 3.7 | M27: 3.7 | N27: 5 | O27: 5 | P27: 0.5
B28: FIESTAS PATRIAS | D28: POLKA (TAPADA LIMEÑA) | F28: 6.5 | G28: 6.5 | H28: 6.5 | I28: 6.5 | J28: 6.5 | K28: 6.5 | L28: 6.5 | M28: 6.5 | N28: 10 | O28: 10
B29: FIESTAS PATRIAS | D29: INCA | G29: 3.5 | H29: 3.5 | I29: 3.5 | J29: 3.5 | K29: 3.5 | L29: 3.5 | M29: 3.5 | N29: 5 | O29: 5
B30: FIESTAS PATRIAS | D30: HUSARES DE JUNIN | G30: 3.7 | H30: 3.7 | I30: 3.7 | J30: 3.7 | K30: 3.7 | L30: 3.7 | M30: 3.7 | N30: 5 | O30: 5 | P30: 0.35
B31: FIESTAS PATRIAS | D31: SAN MARTIN | G31: 3.7 | H31: 3.7 | I31: 3.7 | J31: 3.7 | K31: 3.7 | L31: 3.7 | M31: 3.7 | N31: 5 | O31: 5 | P31: 0.35
B32: FIESTAS PATRIAS | D32: BOLOGNESI | G32: 3.5 | H32: 3.5 | I32: 3.5 | J32: 3.5 | K32: 3.5 | L32: 3.5 | M32: 3.5 | N32: 5 | O32: 5 | P32: 0.35
B33: FIESTAS PATRIAS | D33: ALFONZO UGARTE | G33: 3.5 | H33: 3.5 | I33: 3.5 | J33: 3.5 | K33: 3.5 | L33: 3.5 | M33: 3.5 | N33: 5 | O33: 5 | P33: 0.35
B34: FIESTAS PATRIAS | D34: CONQUISTADOR | G34: 6 | H34: 6 | I34: 6 | J34: 6 | K34: 6 | L34: 6 | M34: 6
B35: FIESTAS PATRIAS | D35: BOLIVAR | G35: 3.7 | H35: 3.7 | I35: 3.7 | J35: 3.7 | K35: 3.7 | L35: 3.7 | M35: 3.7 | N35: 5 | O35: 5 | P35: 0.35
B36: FIESTAS PATRIAS | D36: HUSARINA | G36: 3.5 | H36: 3.5 | I36: 3.5 | J36: 3.5 | K36: 3.5 | L36: 3.5 | M36: 3.5 | N36: 5 | O36: 5 | P36: 0.35
B37: FIESTAS PATRIAS | D37: GUARIPOLERA | G37: 3.5 | H37: 3.5 | I37: 3.5 | J37: 3.5 | K37: 3.5 | L37: 3.5 | M37: 3.5 | N37: 5 | O37: 5 | P37: 0.35
B38: FIESTAS PATRIAS | D38: PARIGUANA | G38: 3 | H38: 3 | I38: 3 | J38: 3 | K38: 3 | L38: 3 | M38: 3 | N38: 5 | O38: 5
B39: FIESTAS PATRIAS | D39: MADRE PATRIA | F39: 3.5 | G39: 3.5 | H39: 3.5 | I39: 3.5 | J39: 3.5 | K39: 3.5 | L39: 3.5 | M39: 3.5 | N39: 5 | O39: 5
B40: FIESTAS PATRIAS | D40: MICAELA BASTIDAS | F40: 3.7 | G40: 3.7 | H40: 3.7 | I40: 3.7 | J40: 3.7 | K40: 3.7 | L40: 3.7 | M40: 3.7 | N40: 5 | O40: 5
B41: FIESTAS PATRIAS | D41: MARIA PARADO B. | F41: 3.7 | G41: 3.7 | H41: 3.7 | I41: 3.7 | J41: 3.7 | K41: 3.7 | L41: 3.7 | M41: 3.7 | N41: 5 | O41: 5
...
